[23/Jul/2016 20:04:56] ERROR [django.request:284] Internal Server Error: /
Traceback (most recent call last):
  File "/Users/devinjackson/anaconda/lib/python2.7/site-packages/django/core/handlers/base.py", line 149, in get_response
    response = self.process_exception_by_middleware(e, request)
  File "/Users/devinjackson/anaconda/lib/python2.7/site-packages/django/core/handlers/base.py", line 147, in get_response
    response = wrapped_callback(request, *callback_args, **callback_kwargs)
  File "/Users/devinjackson/anaconda/lib/python2.7/site-packages/django/views/generic/base.py", line 68, in view
    return self.dispatch(request, *args, **kwargs)
  File "/Users/devinjackson/anaconda/lib/python2.7/site-packages/django/views/generic/base.py", line 88, in dispatch
    return handler(request, *args, **kwargs)
  File "/Users/devinjackson/Documents/WebApps/blog/articles/views.py", line 13, in get
    print "pig" + 5
TypeError: cannot concatenate 'str' and 'int' objects
[23/Jul/2016 20:04:56] ERROR [django.request:284] Internal Server Error: /
Traceback (most recent call last):
  File "/Users/devinjackson/anaconda/lib/python2.7/site-packages/django/core/handlers/base.py", line 149, in get_response
    response = self.process_exception_by_middleware(e, request)
  File "/Users/devinjackson/anaconda/lib/python2.7/site-packages/django/core/handlers/base.py", line 147, in get_response
    response = wrapped_callback(request, *callback_args, **callback_kwargs)
  File "/Users/devinjackson/anaconda/lib/python2.7/site-packages/django/views/generic/base.py", line 68, in view
    return self.dispatch(request, *args, **kwargs)
  File "/Users/devinjackson/anaconda/lib/python2.7/site-packages/django/views/generic/base.py", line 88, in dispatch
    return handler(request, *args, **kwargs)
  File "/Users/devinjackson/Documents/WebApps/blog/articles/views.py", line 13, in get
    print "pig" + 5
TypeError: cannot concatenate 'str' and 'int' objects
[23/Jul/2016 20:04:57] ERROR [django.request:284] Internal Server Error: /favicon.ico
Traceback (most recent call last):
  File "/Users/devinjackson/anaconda/lib/python2.7/site-packages/django/core/handlers/base.py", line 149, in get_response
    response = self.process_exception_by_middleware(e, request)
  File "/Users/devinjackson/anaconda/lib/python2.7/site-packages/django/core/handlers/base.py", line 147, in get_response
    response = wrapped_callback(request, *callback_args, **callback_kwargs)
  File "/Users/devinjackson/anaconda/lib/python2.7/site-packages/django/views/generic/base.py", line 68, in view
    return self.dispatch(request, *args, **kwargs)
  File "/Users/devinjackson/anaconda/lib/python2.7/site-packages/django/views/generic/base.py", line 88, in dispatch
    return handler(request, *args, **kwargs)
  File "/Users/devinjackson/Documents/WebApps/blog/articles/views.py", line 26, in get
    article = Article.objects.get(slug=kwargs['slug'])
  File "/Users/devinjackson/anaconda/lib/python2.7/site-packages/django/db/models/manager.py", line 122, in manager_method
    return getattr(self.get_queryset(), name)(*args, **kwargs)
  File "/Users/devinjackson/anaconda/lib/python2.7/site-packages/django/db/models/query.py", line 387, in get
    self.model._meta.object_name
DoesNotExist: Article matching query does not exist.
[23/Jul/2016 20:06:33] ERROR [django.request:284] Internal Server Error: /
Traceback (most recent call last):
  File "/Users/devinjackson/anaconda/lib/python2.7/site-packages/django/core/handlers/base.py", line 149, in get_response
    response = self.process_exception_by_middleware(e, request)
  File "/Users/devinjackson/anaconda/lib/python2.7/site-packages/django/core/handlers/base.py", line 147, in get_response
    response = wrapped_callback(request, *callback_args, **callback_kwargs)
  File "/Users/devinjackson/anaconda/lib/python2.7/site-packages/django/views/generic/base.py", line 68, in view
    return self.dispatch(request, *args, **kwargs)
  File "/Users/devinjackson/anaconda/lib/python2.7/site-packages/django/views/generic/base.py", line 88, in dispatch
    return handler(request, *args, **kwargs)
  File "/Users/devinjackson/Documents/WebApps/blog/articles/views.py", line 13, in get
    print "pig" + 5
TypeError: cannot concatenate 'str' and 'int' objects
[23/Jul/2016 20:06:33] ERROR [django.request:284] Internal Server Error: /favicon.ico
Traceback (most recent call last):
  File "/Users/devinjackson/anaconda/lib/python2.7/site-packages/django/core/handlers/base.py", line 149, in get_response
    response = self.process_exception_by_middleware(e, request)
  File "/Users/devinjackson/anaconda/lib/python2.7/site-packages/django/core/handlers/base.py", line 147, in get_response
    response = wrapped_callback(request, *callback_args, **callback_kwargs)
  File "/Users/devinjackson/anaconda/lib/python2.7/site-packages/django/views/generic/base.py", line 68, in view
    return self.dispatch(request, *args, **kwargs)
  File "/Users/devinjackson/anaconda/lib/python2.7/site-packages/django/views/generic/base.py", line 88, in dispatch
    return handler(request, *args, **kwargs)
  File "/Users/devinjackson/Documents/WebApps/blog/articles/views.py", line 26, in get
    article = Article.objects.get(slug=kwargs['slug'])
  File "/Users/devinjackson/anaconda/lib/python2.7/site-packages/django/db/models/manager.py", line 122, in manager_method
    return getattr(self.get_queryset(), name)(*args, **kwargs)
  File "/Users/devinjackson/anaconda/lib/python2.7/site-packages/django/db/models/query.py", line 387, in get
    self.model._meta.object_name
DoesNotExist: Article matching query does not exist.
[23/Jul/2016 20:08:40] ERROR [django.request:284] Internal Server Error: /
Traceback (most recent call last):
  File "/Users/devinjackson/anaconda/lib/python2.7/site-packages/django/core/handlers/base.py", line 149, in get_response
    response = self.process_exception_by_middleware(e, request)
  File "/Users/devinjackson/anaconda/lib/python2.7/site-packages/django/core/handlers/base.py", line 147, in get_response
    response = wrapped_callback(request, *callback_args, **callback_kwargs)
  File "/Users/devinjackson/anaconda/lib/python2.7/site-packages/django/views/generic/base.py", line 68, in view
    return self.dispatch(request, *args, **kwargs)
  File "/Users/devinjackson/anaconda/lib/python2.7/site-packages/django/views/generic/base.py", line 88, in dispatch
    return handler(request, *args, **kwargs)
  File "/Users/devinjackson/Documents/WebApps/blog/articles/views.py", line 13, in get
    print "pig" + 5
TypeError: cannot concatenate 'str' and 'int' objects
[23/Jul/2016 20:08:41] ERROR [django.request:284] Internal Server Error: /favicon.ico
Traceback (most recent call last):
  File "/Users/devinjackson/anaconda/lib/python2.7/site-packages/django/core/handlers/base.py", line 149, in get_response
    response = self.process_exception_by_middleware(e, request)
  File "/Users/devinjackson/anaconda/lib/python2.7/site-packages/django/core/handlers/base.py", line 147, in get_response
    response = wrapped_callback(request, *callback_args, **callback_kwargs)
  File "/Users/devinjackson/anaconda/lib/python2.7/site-packages/django/views/generic/base.py", line 68, in view
    return self.dispatch(request, *args, **kwargs)
  File "/Users/devinjackson/anaconda/lib/python2.7/site-packages/django/views/generic/base.py", line 88, in dispatch
    return handler(request, *args, **kwargs)
  File "/Users/devinjackson/Documents/WebApps/blog/articles/views.py", line 26, in get
    article = Article.objects.get(slug=kwargs['slug'])
  File "/Users/devinjackson/anaconda/lib/python2.7/site-packages/django/db/models/manager.py", line 122, in manager_method
    return getattr(self.get_queryset(), name)(*args, **kwargs)
  File "/Users/devinjackson/anaconda/lib/python2.7/site-packages/django/db/models/query.py", line 387, in get
    self.model._meta.object_name
DoesNotExist: Article matching query does not exist.
[23/Jul/2016 20:13:01] ERROR [django.request:284] Internal Server Error: /
Traceback (most recent call last):
  File "/Users/devinjackson/anaconda/lib/python2.7/site-packages/django/core/handlers/base.py", line 149, in get_response
    response = self.process_exception_by_middleware(e, request)
  File "/Users/devinjackson/anaconda/lib/python2.7/site-packages/django/core/handlers/base.py", line 147, in get_response
    response = wrapped_callback(request, *callback_args, **callback_kwargs)
  File "/Users/devinjackson/anaconda/lib/python2.7/site-packages/django/views/generic/base.py", line 68, in view
    return self.dispatch(request, *args, **kwargs)
  File "/Users/devinjackson/anaconda/lib/python2.7/site-packages/django/views/generic/base.py", line 88, in dispatch
    return handler(request, *args, **kwargs)
  File "/Users/devinjackson/Documents/WebApps/blog/articles/views.py", line 13, in get
    print "pig" + 5
TypeError: cannot concatenate 'str' and 'int' objects
[23/Jul/2016 20:13:02] ERROR [django.request:284] Internal Server Error: /favicon.ico
Traceback (most recent call last):
  File "/Users/devinjackson/anaconda/lib/python2.7/site-packages/django/core/handlers/base.py", line 149, in get_response
    response = self.process_exception_by_middleware(e, request)
  File "/Users/devinjackson/anaconda/lib/python2.7/site-packages/django/core/handlers/base.py", line 147, in get_response
    response = wrapped_callback(request, *callback_args, **callback_kwargs)
  File "/Users/devinjackson/anaconda/lib/python2.7/site-packages/django/views/generic/base.py", line 68, in view
    return self.dispatch(request, *args, **kwargs)
  File "/Users/devinjackson/anaconda/lib/python2.7/site-packages/django/views/generic/base.py", line 88, in dispatch
    return handler(request, *args, **kwargs)
  File "/Users/devinjackson/Documents/WebApps/blog/articles/views.py", line 26, in get
    article = Article.objects.get(slug=kwargs['slug'])
  File "/Users/devinjackson/anaconda/lib/python2.7/site-packages/django/db/models/manager.py", line 122, in manager_method
    return getattr(self.get_queryset(), name)(*args, **kwargs)
  File "/Users/devinjackson/anaconda/lib/python2.7/site-packages/django/db/models/query.py", line 387, in get
    self.model._meta.object_name
DoesNotExist: Article matching query does not exist.
[23/Jul/2016 20:13:18] ERROR [django.request:284] Internal Server Error: /static/css/index.css
Traceback (most recent call last):
  File "/Users/devinjackson/anaconda/lib/python2.7/site-packages/django/core/handlers/base.py", line 149, in get_response
    response = self.process_exception_by_middleware(e, request)
  File "/Users/devinjackson/anaconda/lib/python2.7/site-packages/django/core/handlers/base.py", line 147, in get_response
    response = wrapped_callback(request, *callback_args, **callback_kwargs)
  File "/Users/devinjackson/anaconda/lib/python2.7/site-packages/django/views/generic/base.py", line 68, in view
    return self.dispatch(request, *args, **kwargs)
  File "/Users/devinjackson/anaconda/lib/python2.7/site-packages/django/views/generic/base.py", line 88, in dispatch
    return handler(request, *args, **kwargs)
  File "/Users/devinjackson/Documents/WebApps/blog/articles/views.py", line 26, in get
    article = Article.objects.get(slug=kwargs['slug'])
  File "/Users/devinjackson/anaconda/lib/python2.7/site-packages/django/db/models/manager.py", line 122, in manager_method
    return getattr(self.get_queryset(), name)(*args, **kwargs)
  File "/Users/devinjackson/anaconda/lib/python2.7/site-packages/django/db/models/query.py", line 387, in get
    self.model._meta.object_name
DoesNotExist: Article matching query does not exist.
[23/Jul/2016 20:13:18] ERROR [django.request:284] Internal Server Error: /static/scripts/main.js
Traceback (most recent call last):
  File "/Users/devinjackson/anaconda/lib/python2.7/site-packages/django/core/handlers/base.py", line 149, in get_response
    response = self.process_exception_by_middleware(e, request)
  File "/Users/devinjackson/anaconda/lib/python2.7/site-packages/django/core/handlers/base.py", line 147, in get_response
    response = wrapped_callback(request, *callback_args, **callback_kwargs)
  File "/Users/devinjackson/anaconda/lib/python2.7/site-packages/django/views/generic/base.py", line 68, in view
    return self.dispatch(request, *args, **kwargs)
  File "/Users/devinjackson/anaconda/lib/python2.7/site-packages/django/views/generic/base.py", line 88, in dispatch
    return handler(request, *args, **kwargs)
  File "/Users/devinjackson/Documents/WebApps/blog/articles/views.py", line 26, in get
    article = Article.objects.get(slug=kwargs['slug'])
  File "/Users/devinjackson/anaconda/lib/python2.7/site-packages/django/db/models/manager.py", line 122, in manager_method
    return getattr(self.get_queryset(), name)(*args, **kwargs)
  File "/Users/devinjackson/anaconda/lib/python2.7/site-packages/django/db/models/query.py", line 387, in get
    self.model._meta.object_name
DoesNotExist: Article matching query does not exist.
[23/Jul/2016 20:13:18] ERROR [django.request:284] Internal Server Error: /static/scripts/main.js
Traceback (most recent call last):
  File "/Users/devinjackson/anaconda/lib/python2.7/site-packages/django/core/handlers/base.py", line 149, in get_response
    response = self.process_exception_by_middleware(e, request)
  File "/Users/devinjackson/anaconda/lib/python2.7/site-packages/django/core/handlers/base.py", line 147, in get_response
    response = wrapped_callback(request, *callback_args, **callback_kwargs)
  File "/Users/devinjackson/anaconda/lib/python2.7/site-packages/django/views/generic/base.py", line 68, in view
    return self.dispatch(request, *args, **kwargs)
  File "/Users/devinjackson/anaconda/lib/python2.7/site-packages/django/views/generic/base.py", line 88, in dispatch
    return handler(request, *args, **kwargs)
  File "/Users/devinjackson/Documents/WebApps/blog/articles/views.py", line 26, in get
    article = Article.objects.get(slug=kwargs['slug'])
  File "/Users/devinjackson/anaconda/lib/python2.7/site-packages/django/db/models/manager.py", line 122, in manager_method
    return getattr(self.get_queryset(), name)(*args, **kwargs)
  File "/Users/devinjackson/anaconda/lib/python2.7/site-packages/django/db/models/query.py", line 387, in get
    self.model._meta.object_name
DoesNotExist: Article matching query does not exist.
[23/Jul/2016 20:13:19] ERROR [django.request:284] Internal Server Error: /favicon.ico
Traceback (most recent call last):
  File "/Users/devinjackson/anaconda/lib/python2.7/site-packages/django/core/handlers/base.py", line 149, in get_response
    response = self.process_exception_by_middleware(e, request)
  File "/Users/devinjackson/anaconda/lib/python2.7/site-packages/django/core/handlers/base.py", line 147, in get_response
    response = wrapped_callback(request, *callback_args, **callback_kwargs)
  File "/Users/devinjackson/anaconda/lib/python2.7/site-packages/django/views/generic/base.py", line 68, in view
    return self.dispatch(request, *args, **kwargs)
  File "/Users/devinjackson/anaconda/lib/python2.7/site-packages/django/views/generic/base.py", line 88, in dispatch
    return handler(request, *args, **kwargs)
  File "/Users/devinjackson/Documents/WebApps/blog/articles/views.py", line 26, in get
    article = Article.objects.get(slug=kwargs['slug'])
  File "/Users/devinjackson/anaconda/lib/python2.7/site-packages/django/db/models/manager.py", line 122, in manager_method
    return getattr(self.get_queryset(), name)(*args, **kwargs)
  File "/Users/devinjackson/anaconda/lib/python2.7/site-packages/django/db/models/query.py", line 387, in get
    self.model._meta.object_name
DoesNotExist: Article matching query does not exist.
[23/Jul/2016 20:13:22] ERROR [django.request:284] Internal Server Error: /static/css/index.css
Traceback (most recent call last):
  File "/Users/devinjackson/anaconda/lib/python2.7/site-packages/django/core/handlers/base.py", line 149, in get_response
    response = self.process_exception_by_middleware(e, request)
  File "/Users/devinjackson/anaconda/lib/python2.7/site-packages/django/core/handlers/base.py", line 147, in get_response
    response = wrapped_callback(request, *callback_args, **callback_kwargs)
  File "/Users/devinjackson/anaconda/lib/python2.7/site-packages/django/views/generic/base.py", line 68, in view
    return self.dispatch(request, *args, **kwargs)
  File "/Users/devinjackson/anaconda/lib/python2.7/site-packages/django/views/generic/base.py", line 88, in dispatch
    return handler(request, *args, **kwargs)
  File "/Users/devinjackson/Documents/WebApps/blog/articles/views.py", line 26, in get
    article = Article.objects.get(slug=kwargs['slug'])
  File "/Users/devinjackson/anaconda/lib/python2.7/site-packages/django/db/models/manager.py", line 122, in manager_method
    return getattr(self.get_queryset(), name)(*args, **kwargs)
  File "/Users/devinjackson/anaconda/lib/python2.7/site-packages/django/db/models/query.py", line 387, in get
    self.model._meta.object_name
DoesNotExist: Article matching query does not exist.
[23/Jul/2016 20:13:22] ERROR [django.request:284] Internal Server Error: /static/scripts/main.js
Traceback (most recent call last):
  File "/Users/devinjackson/anaconda/lib/python2.7/site-packages/django/core/handlers/base.py", line 149, in get_response
    response = self.process_exception_by_middleware(e, request)
  File "/Users/devinjackson/anaconda/lib/python2.7/site-packages/django/core/handlers/base.py", line 147, in get_response
    response = wrapped_callback(request, *callback_args, **callback_kwargs)
  File "/Users/devinjackson/anaconda/lib/python2.7/site-packages/django/views/generic/base.py", line 68, in view
    return self.dispatch(request, *args, **kwargs)
  File "/Users/devinjackson/anaconda/lib/python2.7/site-packages/django/views/generic/base.py", line 88, in dispatch
    return handler(request, *args, **kwargs)
  File "/Users/devinjackson/Documents/WebApps/blog/articles/views.py", line 26, in get
    article = Article.objects.get(slug=kwargs['slug'])
  File "/Users/devinjackson/anaconda/lib/python2.7/site-packages/django/db/models/manager.py", line 122, in manager_method
    return getattr(self.get_queryset(), name)(*args, **kwargs)
  File "/Users/devinjackson/anaconda/lib/python2.7/site-packages/django/db/models/query.py", line 387, in get
    self.model._meta.object_name
DoesNotExist: Article matching query does not exist.
[23/Jul/2016 20:13:22] ERROR [django.request:284] Internal Server Error: /static/scripts/main.js
Traceback (most recent call last):
  File "/Users/devinjackson/anaconda/lib/python2.7/site-packages/django/core/handlers/base.py", line 149, in get_response
    response = self.process_exception_by_middleware(e, request)
  File "/Users/devinjackson/anaconda/lib/python2.7/site-packages/django/core/handlers/base.py", line 147, in get_response
    response = wrapped_callback(request, *callback_args, **callback_kwargs)
  File "/Users/devinjackson/anaconda/lib/python2.7/site-packages/django/views/generic/base.py", line 68, in view
    return self.dispatch(request, *args, **kwargs)
  File "/Users/devinjackson/anaconda/lib/python2.7/site-packages/django/views/generic/base.py", line 88, in dispatch
    return handler(request, *args, **kwargs)
  File "/Users/devinjackson/Documents/WebApps/blog/articles/views.py", line 26, in get
    article = Article.objects.get(slug=kwargs['slug'])
  File "/Users/devinjackson/anaconda/lib/python2.7/site-packages/django/db/models/manager.py", line 122, in manager_method
    return getattr(self.get_queryset(), name)(*args, **kwargs)
  File "/Users/devinjackson/anaconda/lib/python2.7/site-packages/django/db/models/query.py", line 387, in get
    self.model._meta.object_name
DoesNotExist: Article matching query does not exist.
[23/Jul/2016 20:13:22] ERROR [django.request:284] Internal Server Error: /favicon.ico
Traceback (most recent call last):
  File "/Users/devinjackson/anaconda/lib/python2.7/site-packages/django/core/handlers/base.py", line 149, in get_response
    response = self.process_exception_by_middleware(e, request)
  File "/Users/devinjackson/anaconda/lib/python2.7/site-packages/django/core/handlers/base.py", line 147, in get_response
    response = wrapped_callback(request, *callback_args, **callback_kwargs)
  File "/Users/devinjackson/anaconda/lib/python2.7/site-packages/django/views/generic/base.py", line 68, in view
    return self.dispatch(request, *args, **kwargs)
  File "/Users/devinjackson/anaconda/lib/python2.7/site-packages/django/views/generic/base.py", line 88, in dispatch
    return handler(request, *args, **kwargs)
  File "/Users/devinjackson/Documents/WebApps/blog/articles/views.py", line 26, in get
    article = Article.objects.get(slug=kwargs['slug'])
  File "/Users/devinjackson/anaconda/lib/python2.7/site-packages/django/db/models/manager.py", line 122, in manager_method
    return getattr(self.get_queryset(), name)(*args, **kwargs)
  File "/Users/devinjackson/anaconda/lib/python2.7/site-packages/django/db/models/query.py", line 387, in get
    self.model._meta.object_name
DoesNotExist: Article matching query does not exist.
[23/Jul/2016 20:14:18] ERROR [django.request:284] Internal Server Error: /static/css/index.css
Traceback (most recent call last):
  File "/Users/devinjackson/anaconda/lib/python2.7/site-packages/django/core/handlers/base.py", line 149, in get_response
    response = self.process_exception_by_middleware(e, request)
  File "/Users/devinjackson/anaconda/lib/python2.7/site-packages/django/core/handlers/base.py", line 147, in get_response
    response = wrapped_callback(request, *callback_args, **callback_kwargs)
  File "/Users/devinjackson/anaconda/lib/python2.7/site-packages/django/views/generic/base.py", line 68, in view
    return self.dispatch(request, *args, **kwargs)
  File "/Users/devinjackson/anaconda/lib/python2.7/site-packages/django/views/generic/base.py", line 88, in dispatch
    return handler(request, *args, **kwargs)
  File "/Users/devinjackson/Documents/WebApps/blog/articles/views.py", line 26, in get
    article = Article.objects.get(slug=kwargs['slug'])
  File "/Users/devinjackson/anaconda/lib/python2.7/site-packages/django/db/models/manager.py", line 122, in manager_method
    return getattr(self.get_queryset(), name)(*args, **kwargs)
  File "/Users/devinjackson/anaconda/lib/python2.7/site-packages/django/db/models/query.py", line 387, in get
    self.model._meta.object_name
DoesNotExist: Article matching query does not exist.
[23/Jul/2016 20:14:18] ERROR [django.request:284] Internal Server Error: /static/scripts/main.js
Traceback (most recent call last):
  File "/Users/devinjackson/anaconda/lib/python2.7/site-packages/django/core/handlers/base.py", line 149, in get_response
    response = self.process_exception_by_middleware(e, request)
  File "/Users/devinjackson/anaconda/lib/python2.7/site-packages/django/core/handlers/base.py", line 147, in get_response
    response = wrapped_callback(request, *callback_args, **callback_kwargs)
  File "/Users/devinjackson/anaconda/lib/python2.7/site-packages/django/views/generic/base.py", line 68, in view
    return self.dispatch(request, *args, **kwargs)
  File "/Users/devinjackson/anaconda/lib/python2.7/site-packages/django/views/generic/base.py", line 88, in dispatch
    return handler(request, *args, **kwargs)
  File "/Users/devinjackson/Documents/WebApps/blog/articles/views.py", line 26, in get
    article = Article.objects.get(slug=kwargs['slug'])
  File "/Users/devinjackson/anaconda/lib/python2.7/site-packages/django/db/models/manager.py", line 122, in manager_method
    return getattr(self.get_queryset(), name)(*args, **kwargs)
  File "/Users/devinjackson/anaconda/lib/python2.7/site-packages/django/db/models/query.py", line 387, in get
    self.model._meta.object_name
DoesNotExist: Article matching query does not exist.
[23/Jul/2016 20:14:18] ERROR [django.request:284] Internal Server Error: /static/scripts/main.js
Traceback (most recent call last):
  File "/Users/devinjackson/anaconda/lib/python2.7/site-packages/django/core/handlers/base.py", line 149, in get_response
    response = self.process_exception_by_middleware(e, request)
  File "/Users/devinjackson/anaconda/lib/python2.7/site-packages/django/core/handlers/base.py", line 147, in get_response
    response = wrapped_callback(request, *callback_args, **callback_kwargs)
  File "/Users/devinjackson/anaconda/lib/python2.7/site-packages/django/views/generic/base.py", line 68, in view
    return self.dispatch(request, *args, **kwargs)
  File "/Users/devinjackson/anaconda/lib/python2.7/site-packages/django/views/generic/base.py", line 88, in dispatch
    return handler(request, *args, **kwargs)
  File "/Users/devinjackson/Documents/WebApps/blog/articles/views.py", line 26, in get
    article = Article.objects.get(slug=kwargs['slug'])
  File "/Users/devinjackson/anaconda/lib/python2.7/site-packages/django/db/models/manager.py", line 122, in manager_method
    return getattr(self.get_queryset(), name)(*args, **kwargs)
  File "/Users/devinjackson/anaconda/lib/python2.7/site-packages/django/db/models/query.py", line 387, in get
    self.model._meta.object_name
DoesNotExist: Article matching query does not exist.
[23/Jul/2016 20:14:18] ERROR [django.request:284] Internal Server Error: /favicon.ico
Traceback (most recent call last):
  File "/Users/devinjackson/anaconda/lib/python2.7/site-packages/django/core/handlers/base.py", line 149, in get_response
    response = self.process_exception_by_middleware(e, request)
  File "/Users/devinjackson/anaconda/lib/python2.7/site-packages/django/core/handlers/base.py", line 147, in get_response
    response = wrapped_callback(request, *callback_args, **callback_kwargs)
  File "/Users/devinjackson/anaconda/lib/python2.7/site-packages/django/views/generic/base.py", line 68, in view
    return self.dispatch(request, *args, **kwargs)
  File "/Users/devinjackson/anaconda/lib/python2.7/site-packages/django/views/generic/base.py", line 88, in dispatch
    return handler(request, *args, **kwargs)
  File "/Users/devinjackson/Documents/WebApps/blog/articles/views.py", line 26, in get
    article = Article.objects.get(slug=kwargs['slug'])
  File "/Users/devinjackson/anaconda/lib/python2.7/site-packages/django/db/models/manager.py", line 122, in manager_method
    return getattr(self.get_queryset(), name)(*args, **kwargs)
  File "/Users/devinjackson/anaconda/lib/python2.7/site-packages/django/db/models/query.py", line 387, in get
    self.model._meta.object_name
DoesNotExist: Article matching query does not exist.
[23/Jul/2016 20:14:33] ERROR [django.request:284] Internal Server Error: /static/css/index.css
Traceback (most recent call last):
  File "/Users/devinjackson/anaconda/lib/python2.7/site-packages/django/core/handlers/base.py", line 149, in get_response
    response = self.process_exception_by_middleware(e, request)
  File "/Users/devinjackson/anaconda/lib/python2.7/site-packages/django/core/handlers/base.py", line 147, in get_response
    response = wrapped_callback(request, *callback_args, **callback_kwargs)
  File "/Users/devinjackson/anaconda/lib/python2.7/site-packages/django/views/generic/base.py", line 68, in view
    return self.dispatch(request, *args, **kwargs)
  File "/Users/devinjackson/anaconda/lib/python2.7/site-packages/django/views/generic/base.py", line 88, in dispatch
    return handler(request, *args, **kwargs)
  File "/Users/devinjackson/Documents/WebApps/blog/articles/views.py", line 26, in get
    article = Article.objects.get(slug=kwargs['slug'])
  File "/Users/devinjackson/anaconda/lib/python2.7/site-packages/django/db/models/manager.py", line 122, in manager_method
    return getattr(self.get_queryset(), name)(*args, **kwargs)
  File "/Users/devinjackson/anaconda/lib/python2.7/site-packages/django/db/models/query.py", line 387, in get
    self.model._meta.object_name
DoesNotExist: Article matching query does not exist.
[23/Jul/2016 20:14:33] ERROR [django.request:284] Internal Server Error: /static/scripts/main.js
Traceback (most recent call last):
  File "/Users/devinjackson/anaconda/lib/python2.7/site-packages/django/core/handlers/base.py", line 149, in get_response
    response = self.process_exception_by_middleware(e, request)
  File "/Users/devinjackson/anaconda/lib/python2.7/site-packages/django/core/handlers/base.py", line 147, in get_response
    response = wrapped_callback(request, *callback_args, **callback_kwargs)
  File "/Users/devinjackson/anaconda/lib/python2.7/site-packages/django/views/generic/base.py", line 68, in view
    return self.dispatch(request, *args, **kwargs)
  File "/Users/devinjackson/anaconda/lib/python2.7/site-packages/django/views/generic/base.py", line 88, in dispatch
    return handler(request, *args, **kwargs)
  File "/Users/devinjackson/Documents/WebApps/blog/articles/views.py", line 26, in get
    article = Article.objects.get(slug=kwargs['slug'])
  File "/Users/devinjackson/anaconda/lib/python2.7/site-packages/django/db/models/manager.py", line 122, in manager_method
    return getattr(self.get_queryset(), name)(*args, **kwargs)
  File "/Users/devinjackson/anaconda/lib/python2.7/site-packages/django/db/models/query.py", line 387, in get
    self.model._meta.object_name
DoesNotExist: Article matching query does not exist.
[23/Jul/2016 20:14:33] ERROR [django.request:284] Internal Server Error: /static/scripts/main.js
Traceback (most recent call last):
  File "/Users/devinjackson/anaconda/lib/python2.7/site-packages/django/core/handlers/base.py", line 149, in get_response
    response = self.process_exception_by_middleware(e, request)
  File "/Users/devinjackson/anaconda/lib/python2.7/site-packages/django/core/handlers/base.py", line 147, in get_response
    response = wrapped_callback(request, *callback_args, **callback_kwargs)
  File "/Users/devinjackson/anaconda/lib/python2.7/site-packages/django/views/generic/base.py", line 68, in view
    return self.dispatch(request, *args, **kwargs)
  File "/Users/devinjackson/anaconda/lib/python2.7/site-packages/django/views/generic/base.py", line 88, in dispatch
    return handler(request, *args, **kwargs)
  File "/Users/devinjackson/Documents/WebApps/blog/articles/views.py", line 26, in get
    article = Article.objects.get(slug=kwargs['slug'])
  File "/Users/devinjackson/anaconda/lib/python2.7/site-packages/django/db/models/manager.py", line 122, in manager_method
    return getattr(self.get_queryset(), name)(*args, **kwargs)
  File "/Users/devinjackson/anaconda/lib/python2.7/site-packages/django/db/models/query.py", line 387, in get
    self.model._meta.object_name
DoesNotExist: Article matching query does not exist.
[23/Jul/2016 20:14:34] ERROR [django.request:284] Internal Server Error: /favicon.ico
Traceback (most recent call last):
  File "/Users/devinjackson/anaconda/lib/python2.7/site-packages/django/core/handlers/base.py", line 149, in get_response
    response = self.process_exception_by_middleware(e, request)
  File "/Users/devinjackson/anaconda/lib/python2.7/site-packages/django/core/handlers/base.py", line 147, in get_response
    response = wrapped_callback(request, *callback_args, **callback_kwargs)
  File "/Users/devinjackson/anaconda/lib/python2.7/site-packages/django/views/generic/base.py", line 68, in view
    return self.dispatch(request, *args, **kwargs)
  File "/Users/devinjackson/anaconda/lib/python2.7/site-packages/django/views/generic/base.py", line 88, in dispatch
    return handler(request, *args, **kwargs)
  File "/Users/devinjackson/Documents/WebApps/blog/articles/views.py", line 26, in get
    article = Article.objects.get(slug=kwargs['slug'])
  File "/Users/devinjackson/anaconda/lib/python2.7/site-packages/django/db/models/manager.py", line 122, in manager_method
    return getattr(self.get_queryset(), name)(*args, **kwargs)
  File "/Users/devinjackson/anaconda/lib/python2.7/site-packages/django/db/models/query.py", line 387, in get
    self.model._meta.object_name
DoesNotExist: Article matching query does not exist.
[23/Jul/2016 20:14:35] ERROR [django.request:284] Internal Server Error: /static/css/index.css
Traceback (most recent call last):
  File "/Users/devinjackson/anaconda/lib/python2.7/site-packages/django/core/handlers/base.py", line 149, in get_response
    response = self.process_exception_by_middleware(e, request)
  File "/Users/devinjackson/anaconda/lib/python2.7/site-packages/django/core/handlers/base.py", line 147, in get_response
    response = wrapped_callback(request, *callback_args, **callback_kwargs)
  File "/Users/devinjackson/anaconda/lib/python2.7/site-packages/django/views/generic/base.py", line 68, in view
    return self.dispatch(request, *args, **kwargs)
  File "/Users/devinjackson/anaconda/lib/python2.7/site-packages/django/views/generic/base.py", line 88, in dispatch
    return handler(request, *args, **kwargs)
  File "/Users/devinjackson/Documents/WebApps/blog/articles/views.py", line 26, in get
    article = Article.objects.get(slug=kwargs['slug'])
  File "/Users/devinjackson/anaconda/lib/python2.7/site-packages/django/db/models/manager.py", line 122, in manager_method
    return getattr(self.get_queryset(), name)(*args, **kwargs)
  File "/Users/devinjackson/anaconda/lib/python2.7/site-packages/django/db/models/query.py", line 387, in get
    self.model._meta.object_name
DoesNotExist: Article matching query does not exist.
[23/Jul/2016 20:14:35] ERROR [django.request:284] Internal Server Error: /static/scripts/main.js
Traceback (most recent call last):
  File "/Users/devinjackson/anaconda/lib/python2.7/site-packages/django/core/handlers/base.py", line 149, in get_response
    response = self.process_exception_by_middleware(e, request)
  File "/Users/devinjackson/anaconda/lib/python2.7/site-packages/django/core/handlers/base.py", line 147, in get_response
    response = wrapped_callback(request, *callback_args, **callback_kwargs)
  File "/Users/devinjackson/anaconda/lib/python2.7/site-packages/django/views/generic/base.py", line 68, in view
    return self.dispatch(request, *args, **kwargs)
  File "/Users/devinjackson/anaconda/lib/python2.7/site-packages/django/views/generic/base.py", line 88, in dispatch
    return handler(request, *args, **kwargs)
  File "/Users/devinjackson/Documents/WebApps/blog/articles/views.py", line 26, in get
    article = Article.objects.get(slug=kwargs['slug'])
  File "/Users/devinjackson/anaconda/lib/python2.7/site-packages/django/db/models/manager.py", line 122, in manager_method
    return getattr(self.get_queryset(), name)(*args, **kwargs)
  File "/Users/devinjackson/anaconda/lib/python2.7/site-packages/django/db/models/query.py", line 387, in get
    self.model._meta.object_name
DoesNotExist: Article matching query does not exist.
[23/Jul/2016 20:14:35] ERROR [django.request:284] Internal Server Error: /static/scripts/main.js
Traceback (most recent call last):
  File "/Users/devinjackson/anaconda/lib/python2.7/site-packages/django/core/handlers/base.py", line 149, in get_response
    response = self.process_exception_by_middleware(e, request)
  File "/Users/devinjackson/anaconda/lib/python2.7/site-packages/django/core/handlers/base.py", line 147, in get_response
    response = wrapped_callback(request, *callback_args, **callback_kwargs)
  File "/Users/devinjackson/anaconda/lib/python2.7/site-packages/django/views/generic/base.py", line 68, in view
    return self.dispatch(request, *args, **kwargs)
  File "/Users/devinjackson/anaconda/lib/python2.7/site-packages/django/views/generic/base.py", line 88, in dispatch
    return handler(request, *args, **kwargs)
  File "/Users/devinjackson/Documents/WebApps/blog/articles/views.py", line 26, in get
    article = Article.objects.get(slug=kwargs['slug'])
  File "/Users/devinjackson/anaconda/lib/python2.7/site-packages/django/db/models/manager.py", line 122, in manager_method
    return getattr(self.get_queryset(), name)(*args, **kwargs)
  File "/Users/devinjackson/anaconda/lib/python2.7/site-packages/django/db/models/query.py", line 387, in get
    self.model._meta.object_name
DoesNotExist: Article matching query does not exist.
[23/Jul/2016 20:14:36] ERROR [django.request:284] Internal Server Error: /favicon.ico
Traceback (most recent call last):
  File "/Users/devinjackson/anaconda/lib/python2.7/site-packages/django/core/handlers/base.py", line 149, in get_response
    response = self.process_exception_by_middleware(e, request)
  File "/Users/devinjackson/anaconda/lib/python2.7/site-packages/django/core/handlers/base.py", line 147, in get_response
    response = wrapped_callback(request, *callback_args, **callback_kwargs)
  File "/Users/devinjackson/anaconda/lib/python2.7/site-packages/django/views/generic/base.py", line 68, in view
    return self.dispatch(request, *args, **kwargs)
  File "/Users/devinjackson/anaconda/lib/python2.7/site-packages/django/views/generic/base.py", line 88, in dispatch
    return handler(request, *args, **kwargs)
  File "/Users/devinjackson/Documents/WebApps/blog/articles/views.py", line 26, in get
    article = Article.objects.get(slug=kwargs['slug'])
  File "/Users/devinjackson/anaconda/lib/python2.7/site-packages/django/db/models/manager.py", line 122, in manager_method
    return getattr(self.get_queryset(), name)(*args, **kwargs)
  File "/Users/devinjackson/anaconda/lib/python2.7/site-packages/django/db/models/query.py", line 387, in get
    self.model._meta.object_name
DoesNotExist: Article matching query does not exist.
[23/Jul/2016 20:16:25] ERROR [django.request:284] Internal Server Error: /static/css/index.css
Traceback (most recent call last):
  File "/Users/devinjackson/anaconda/lib/python2.7/site-packages/django/core/handlers/base.py", line 149, in get_response
    response = self.process_exception_by_middleware(e, request)
  File "/Users/devinjackson/anaconda/lib/python2.7/site-packages/django/core/handlers/base.py", line 147, in get_response
    response = wrapped_callback(request, *callback_args, **callback_kwargs)
  File "/Users/devinjackson/anaconda/lib/python2.7/site-packages/django/views/generic/base.py", line 68, in view
    return self.dispatch(request, *args, **kwargs)
  File "/Users/devinjackson/anaconda/lib/python2.7/site-packages/django/views/generic/base.py", line 88, in dispatch
    return handler(request, *args, **kwargs)
  File "/Users/devinjackson/Documents/WebApps/blog/articles/views.py", line 25, in get
    article = Article.objects.get(slug=kwargs['slug'])
  File "/Users/devinjackson/anaconda/lib/python2.7/site-packages/django/db/models/manager.py", line 122, in manager_method
    return getattr(self.get_queryset(), name)(*args, **kwargs)
  File "/Users/devinjackson/anaconda/lib/python2.7/site-packages/django/db/models/query.py", line 387, in get
    self.model._meta.object_name
DoesNotExist: Article matching query does not exist.
[23/Jul/2016 20:16:25] ERROR [django.request:284] Internal Server Error: /static/scripts/main.js
Traceback (most recent call last):
  File "/Users/devinjackson/anaconda/lib/python2.7/site-packages/django/core/handlers/base.py", line 149, in get_response
    response = self.process_exception_by_middleware(e, request)
  File "/Users/devinjackson/anaconda/lib/python2.7/site-packages/django/core/handlers/base.py", line 147, in get_response
    response = wrapped_callback(request, *callback_args, **callback_kwargs)
  File "/Users/devinjackson/anaconda/lib/python2.7/site-packages/django/views/generic/base.py", line 68, in view
    return self.dispatch(request, *args, **kwargs)
  File "/Users/devinjackson/anaconda/lib/python2.7/site-packages/django/views/generic/base.py", line 88, in dispatch
    return handler(request, *args, **kwargs)
  File "/Users/devinjackson/Documents/WebApps/blog/articles/views.py", line 25, in get
    article = Article.objects.get(slug=kwargs['slug'])
  File "/Users/devinjackson/anaconda/lib/python2.7/site-packages/django/db/models/manager.py", line 122, in manager_method
    return getattr(self.get_queryset(), name)(*args, **kwargs)
  File "/Users/devinjackson/anaconda/lib/python2.7/site-packages/django/db/models/query.py", line 387, in get
    self.model._meta.object_name
DoesNotExist: Article matching query does not exist.
[23/Jul/2016 20:16:25] ERROR [django.request:284] Internal Server Error: /static/scripts/main.js
Traceback (most recent call last):
  File "/Users/devinjackson/anaconda/lib/python2.7/site-packages/django/core/handlers/base.py", line 149, in get_response
    response = self.process_exception_by_middleware(e, request)
  File "/Users/devinjackson/anaconda/lib/python2.7/site-packages/django/core/handlers/base.py", line 147, in get_response
    response = wrapped_callback(request, *callback_args, **callback_kwargs)
  File "/Users/devinjackson/anaconda/lib/python2.7/site-packages/django/views/generic/base.py", line 68, in view
    return self.dispatch(request, *args, **kwargs)
  File "/Users/devinjackson/anaconda/lib/python2.7/site-packages/django/views/generic/base.py", line 88, in dispatch
    return handler(request, *args, **kwargs)
  File "/Users/devinjackson/Documents/WebApps/blog/articles/views.py", line 25, in get
    article = Article.objects.get(slug=kwargs['slug'])
  File "/Users/devinjackson/anaconda/lib/python2.7/site-packages/django/db/models/manager.py", line 122, in manager_method
    return getattr(self.get_queryset(), name)(*args, **kwargs)
  File "/Users/devinjackson/anaconda/lib/python2.7/site-packages/django/db/models/query.py", line 387, in get
    self.model._meta.object_name
DoesNotExist: Article matching query does not exist.
[23/Jul/2016 20:16:25] ERROR [django.request:284] Internal Server Error: /static/img/favicon.ico
Traceback (most recent call last):
  File "/Users/devinjackson/anaconda/lib/python2.7/site-packages/django/core/handlers/base.py", line 149, in get_response
    response = self.process_exception_by_middleware(e, request)
  File "/Users/devinjackson/anaconda/lib/python2.7/site-packages/django/core/handlers/base.py", line 147, in get_response
    response = wrapped_callback(request, *callback_args, **callback_kwargs)
  File "/Users/devinjackson/anaconda/lib/python2.7/site-packages/django/views/generic/base.py", line 68, in view
    return self.dispatch(request, *args, **kwargs)
  File "/Users/devinjackson/anaconda/lib/python2.7/site-packages/django/views/generic/base.py", line 88, in dispatch
    return handler(request, *args, **kwargs)
  File "/Users/devinjackson/Documents/WebApps/blog/articles/views.py", line 25, in get
    article = Article.objects.get(slug=kwargs['slug'])
  File "/Users/devinjackson/anaconda/lib/python2.7/site-packages/django/db/models/manager.py", line 122, in manager_method
    return getattr(self.get_queryset(), name)(*args, **kwargs)
  File "/Users/devinjackson/anaconda/lib/python2.7/site-packages/django/db/models/query.py", line 387, in get
    self.model._meta.object_name
DoesNotExist: Article matching query does not exist.
[23/Jul/2016 20:24:29] ERROR [django.request:284] Internal Server Error: /montypython666/
Traceback (most recent call last):
  File "/Users/devinjackson/anaconda/lib/python2.7/site-packages/django/core/handlers/base.py", line 149, in get_response
    response = self.process_exception_by_middleware(e, request)
  File "/Users/devinjackson/anaconda/lib/python2.7/site-packages/django/core/handlers/base.py", line 147, in get_response
    response = wrapped_callback(request, *callback_args, **callback_kwargs)
  File "/Users/devinjackson/anaconda/lib/python2.7/site-packages/django/views/generic/base.py", line 68, in view
    return self.dispatch(request, *args, **kwargs)
  File "/Users/devinjackson/anaconda/lib/python2.7/site-packages/django/views/generic/base.py", line 88, in dispatch
    return handler(request, *args, **kwargs)
  File "/Users/devinjackson/Documents/WebApps/blog/articles/views.py", line 25, in get
    article = Article.objects.get(slug=kwargs['slug'])
  File "/Users/devinjackson/anaconda/lib/python2.7/site-packages/django/db/models/manager.py", line 122, in manager_method
    return getattr(self.get_queryset(), name)(*args, **kwargs)
  File "/Users/devinjackson/anaconda/lib/python2.7/site-packages/django/db/models/query.py", line 387, in get
    self.model._meta.object_name
DoesNotExist: Article matching query does not exist.
[23/Jul/2016 20:24:29] ERROR [django.request:284] Internal Server Error: /favicon.ico
Traceback (most recent call last):
  File "/Users/devinjackson/anaconda/lib/python2.7/site-packages/django/core/handlers/base.py", line 149, in get_response
    response = self.process_exception_by_middleware(e, request)
  File "/Users/devinjackson/anaconda/lib/python2.7/site-packages/django/core/handlers/base.py", line 147, in get_response
    response = wrapped_callback(request, *callback_args, **callback_kwargs)
  File "/Users/devinjackson/anaconda/lib/python2.7/site-packages/django/views/generic/base.py", line 68, in view
    return self.dispatch(request, *args, **kwargs)
  File "/Users/devinjackson/anaconda/lib/python2.7/site-packages/django/views/generic/base.py", line 88, in dispatch
    return handler(request, *args, **kwargs)
  File "/Users/devinjackson/Documents/WebApps/blog/articles/views.py", line 25, in get
    article = Article.objects.get(slug=kwargs['slug'])
  File "/Users/devinjackson/anaconda/lib/python2.7/site-packages/django/db/models/manager.py", line 122, in manager_method
    return getattr(self.get_queryset(), name)(*args, **kwargs)
  File "/Users/devinjackson/anaconda/lib/python2.7/site-packages/django/db/models/query.py", line 387, in get
    self.model._meta.object_name
DoesNotExist: Article matching query does not exist.
[23/Jul/2016 20:24:33] ERROR [django.request:284] Internal Server Error: /favicon.ico
Traceback (most recent call last):
  File "/Users/devinjackson/anaconda/lib/python2.7/site-packages/django/core/handlers/base.py", line 149, in get_response
    response = self.process_exception_by_middleware(e, request)
  File "/Users/devinjackson/anaconda/lib/python2.7/site-packages/django/core/handlers/base.py", line 147, in get_response
    response = wrapped_callback(request, *callback_args, **callback_kwargs)
  File "/Users/devinjackson/anaconda/lib/python2.7/site-packages/django/views/generic/base.py", line 68, in view
    return self.dispatch(request, *args, **kwargs)
  File "/Users/devinjackson/anaconda/lib/python2.7/site-packages/django/views/generic/base.py", line 88, in dispatch
    return handler(request, *args, **kwargs)
  File "/Users/devinjackson/Documents/WebApps/blog/articles/views.py", line 25, in get
    article = Article.objects.get(slug=kwargs['slug'])
  File "/Users/devinjackson/anaconda/lib/python2.7/site-packages/django/db/models/manager.py", line 122, in manager_method
    return getattr(self.get_queryset(), name)(*args, **kwargs)
  File "/Users/devinjackson/anaconda/lib/python2.7/site-packages/django/db/models/query.py", line 387, in get
    self.model._meta.object_name
DoesNotExist: Article matching query does not exist.
[23/Jul/2016 20:24:52] ERROR [django.request:284] Internal Server Error: /montypython666/
Traceback (most recent call last):
  File "/Users/devinjackson/anaconda/lib/python2.7/site-packages/django/core/handlers/base.py", line 149, in get_response
    response = self.process_exception_by_middleware(e, request)
  File "/Users/devinjackson/anaconda/lib/python2.7/site-packages/django/core/handlers/base.py", line 147, in get_response
    response = wrapped_callback(request, *callback_args, **callback_kwargs)
  File "/Users/devinjackson/anaconda/lib/python2.7/site-packages/django/views/generic/base.py", line 68, in view
    return self.dispatch(request, *args, **kwargs)
  File "/Users/devinjackson/anaconda/lib/python2.7/site-packages/django/views/generic/base.py", line 88, in dispatch
    return handler(request, *args, **kwargs)
  File "/Users/devinjackson/Documents/WebApps/blog/articles/views.py", line 25, in get
    article = Article.objects.get(slug=kwargs['slug'])
  File "/Users/devinjackson/anaconda/lib/python2.7/site-packages/django/db/models/manager.py", line 122, in manager_method
    return getattr(self.get_queryset(), name)(*args, **kwargs)
  File "/Users/devinjackson/anaconda/lib/python2.7/site-packages/django/db/models/query.py", line 387, in get
    self.model._meta.object_name
DoesNotExist: Article matching query does not exist.
[23/Jul/2016 20:24:53] ERROR [django.request:284] Internal Server Error: /favicon.ico
Traceback (most recent call last):
  File "/Users/devinjackson/anaconda/lib/python2.7/site-packages/django/core/handlers/base.py", line 149, in get_response
    response = self.process_exception_by_middleware(e, request)
  File "/Users/devinjackson/anaconda/lib/python2.7/site-packages/django/core/handlers/base.py", line 147, in get_response
    response = wrapped_callback(request, *callback_args, **callback_kwargs)
  File "/Users/devinjackson/anaconda/lib/python2.7/site-packages/django/views/generic/base.py", line 68, in view
    return self.dispatch(request, *args, **kwargs)
  File "/Users/devinjackson/anaconda/lib/python2.7/site-packages/django/views/generic/base.py", line 88, in dispatch
    return handler(request, *args, **kwargs)
  File "/Users/devinjackson/Documents/WebApps/blog/articles/views.py", line 25, in get
    article = Article.objects.get(slug=kwargs['slug'])
  File "/Users/devinjackson/anaconda/lib/python2.7/site-packages/django/db/models/manager.py", line 122, in manager_method
    return getattr(self.get_queryset(), name)(*args, **kwargs)
  File "/Users/devinjackson/anaconda/lib/python2.7/site-packages/django/db/models/query.py", line 387, in get
    self.model._meta.object_name
DoesNotExist: Article matching query does not exist.
